Workbook

Sheet Catálogo
A1: Catálogo — Gêmeos do iPhone
A2: Exportado do sistema em 2026-08-15 · 89 produtos
A4: ID | B4: Categoria | C4: Modelo | D4: Memória / Tamanho | E4: Cor | F4: Condição | G4: Bateria % | H4: Avarias | I4: IMEI | J4: Entrada | K4: Custo | L4: Venda | M4: Lucro | N4: Margem | O4: Qtd | P4: Controle | Q4: Situação | R4: Tem foto | S4: Na vitrine
A5: 1 | B5: iPhone | C5: iPhone 7 Plus | D5: 32GB | E5: Vermelho | F5: Vitrine | G5: 82 | I5: 35561086577404 | J5: 02/08/2026 | K5: 348 | L5: 490 | M5: =L5-K5 -> 142 | N5: =IFERROR((L5-K5)/L5,"") -> 0.28979592 | O5: 1 | P5: peça única | Q5: em estoque | R5: não | S5: sim
A6: 2 | B6: iPhone | C6: iPhone 7 Plus | D6: 32GB | E6: Prata | F6: Usado | G6: 98 | I6: 35269446390991 | J6: 10/08/2026 | K6: 284 | L6: 410 | M6: =L6-K6 -> 126 | N6: =IFERROR((L6-K6)/L6,"") -> 0.30731707 | O6: 1 | P6: peça única | Q6: em estoque | R6: não | S6: sim
A7: 3 | B7: iPhone | C7: iPhone 8 | D7: 128GB | E7: Cinza-espacial | F7: Usado | G7: 94 | I7: 35876272518136 | J7: 06/08/2026 | K7: 324 | L7: 440 | M7: =L7-K7 -> 116 | N7: =IFERROR((L7-K7)/L7,"") -> 0.26363636 | O7: 1 | P7: peça única | Q7: em estoque | R7: não | S7: sim
A8: 4 | B8: iPhone | C8: iPhone 8 | D8: 64GB | E8: Cinza-espacial | F8: Novo (lacrado) | G8: 100 | I8: 35994158923895 | J8: 07/08/2026 | K8: 527 | L8: 680 | M8: =L8-K8 -> 153 | N8: =IFERROR((L8-K8)/L8,"") -> 0.225 | O8: 1 | P8: peça única | Q8: em estoque | R8: não | S8: sim
A9: 5 | B9: iPhone | C9: iPhone 8 Plus | D9: 64GB | E9: Prata | F9: Vitrine | G9: 84 | I9: 35676850427402 | J9: 07/08/2026 | K9: 460 | L9: 670 | M9: =L9-K9 -> 210 | N9: =IFERROR((L9-K9)/L9,"") -> 0.31343284 | O9: 1 | P9: peça única | Q9: em estoque | R9: não | S9: sim
A10: 6 | B10: iPhone | C10: iPhone 8 Plus | D10: 128GB | E10: Prata | F10: Novo (lacrado) | G10: 100 | I10: 35273502158260 | J10: 07/08/2026 | K10: 679 | L10: 850 | M10: =L10-K10 -> 171 | N10: =IFERROR((L10-K10)/L10,"") -> 0.20117647 | O10: 1 | P10: peça única | Q10: em estoque | R10: não | S10: sim
A11: 7 | B11: iPhone | C11: iPhone 8 Plus | D11: 256GB | E11: Prata | F11: Novo (lacrado) | G11: 100 | I11: 35731407268066 | J11: 12/08/2026 | K11: 633 | L11: 850 | M11: =L11-K11 -> 217 | N11: =IFERROR((L11-K11)/L11,"") -> 0.25529412 | O11: 1 | P11: peça única | Q11: em estoque | R11: não | S11: sim
A12: 8 | B12: iPhone | C12: iPhone XR | D12: 256GB | E12: Amarelo | F12: Seminovo | G12: 86 | H12: Tela trincada | I12: 35187715126728 | J12: 08/08/2026 | K12: 230 | L12: 330 | M12: =L12-K12 -> 100 | N12: =IFERROR((L12-K12)/L12,"") -> 0.3030303 | O12: 1 | P12: peça única | Q12: em estoque | R12: não | S12: sim
A13: 9 | B13: iPhone | C13: iPhone XR | D13: 128GB | E13: Preto | F13: Seminovo | G13: 82 | I13: 35985239413731 | J13: 04/08/2026 | K13: 571 | L13: 740 | M13: =L13-K13 -> 169 | N13: =IFERROR((L13-K13)/L13,"") -> 0.22837838 | O13: 1 | P13: peça única | Q13: em estoque | R13: não | S13: sim
A14: 10 | B14: iPhone | C14: iPhone XS | D14: 512GB | E14: Prata | F14: Usado | G14: 87 | I14: 35979507388029 | J14: 11/08/2026 | K14: 550 | L14: 710 | M14: =L14-K14 -> 160 | N14: =IFERROR((L14-K14)/L14,"") -> 0.22535211 | O14: 1 | P14: peça única | Q14: em estoque | R14: não | S14: sim
A15: 11 | B15: iPhone | C15: iPhone XS | D15: 64GB | E15: Prata | F15: Vitrine | G15: 89 | H15: Face ID não funciona | I15: 35380192501916 | J15: 08/08/2026 | K15: 419 | L15: 560 | M15: =L15-K15 -> 141 | N15: =IFERROR((L15-K15)/L15,"") -> 0.25178571 | O15: 1 | P15: peça única | Q15: em estoque | R15: não | S15: sim
A16: 12 | B16: iPhone | C16: iPhone 11 | D16: 128GB | E16: Vermelho | F16: Seminovo | G16: 76 | H16: Marcas de uso na lateral | I16: 35212636485462 | J16: 05/08/2026 | K16: 629 | L16: 880 | M16: =L16-K16 -> 251 | N16: =IFERROR((L16-K16)/L16,"") -> 0.28522727 | O16: 1 | P16: peça única | Q16: em estoque | R16: não | S16: sim
A17: 13 | B17: iPhone | C17: iPhone 11 Pro Max | D17: 256GB | E17: Verde-meia-noite | F17: Vitrine | G17: 99 | I17: 35579431213384 | J17: 02/08/2026 | K17: 1347 | L17: 1850 | M17: =L17-K17 -> 503 | N17: =IFERROR((L17-K17)/L17,"") -> 0.27189189 | O17: 1 | P17: peça única | Q17: em estoque | R17: não | S17: sim
A18: 14 | B18: iPhone | C18: iPhone 12 mini | D18: 64GB | E18: Azul | F18: Seminovo | G18: 77 | H18: Marcas de uso na lateral | I18: 35382665654886 | J18: 04/08/2026 | K18: 690 | L18: 980 | M18: =L18-K18 -> 290 | N18: =IFERROR((L18-K18)/L18,"") -> 0.29591837 | O18: 1 | P18: peça única | Q18: em estoque | R18: não | S18: sim
A19: 15 | B19: iPhone | C19: iPhone 12 mini | D19: 256GB | E19: Preto | F19: Usado | G19: 80 | H19: Face ID não funciona | I19: 35422324300129 | J19: 03/08/2026 | K19: 401 | L19: 560 | M19: =L19-K19 -> 159 | N19: =IFERROR((L19-K19)/L19,"") -> 0.28392857 | O19: 1 | P19: peça única | Q19: em estoque | R19: não | S19: sim
A20: 16 | B20: iPhone | C20: iPhone 12 mini | D20: 128GB | E20: Azul | F20: Usado | G20: 94 | H20: Face ID não funciona | I20: 35363964450822 | J20: 06/08/2026 | K20: 481 | L20: 660 | M20: =L20-K20 -> 179 | N20: =IFERROR((L20-K20)/L20,"") -> 0.27121212 | O20: 1 | P20: peça única | Q20: em estoque | R20: não | S20: sim
A21: 17 | B21: iPhone | C21: iPhone 12 | D21: 64GB | E21: Azul | F21: Seminovo | G21: 78 | H21: Câmera com risco | I21: 35582862272581 | J21: 11/08/2026 | K21: 824 | L21: 1050 | M21: =L21-K21 -> 226 | N21: =IFERROR((L21-K21)/L21,"") -> 0.2152381 | O21: 1 | P21: peça única | Q21: em estoque | R21: não | S21: sim
A22: 18 | B22: iPhone | C22: iPhone 12 Pro | D22: 128GB | E22: Azul-pacífico | F22: Usado | G22: 81 | I22: 35831105986202 | J22: 08/08/2026 | K22: 967 | L22: 1340 | M22: =L22-K22 -> 373 | N22: =IFERROR((L22-K22)/L22,"") -> 0.27835821 | O22: 1 | P22: peça única | Q22: em estoque | R22: não | S22: sim
A23: 19 | B23: iPhone | C23: iPhone 12 Pro | D23: 512GB | E23: Azul-pacífico | F23: Vitrine | G23: 98 | I23: 35978105217292 | J23: 01/08/2026 | K23: 1499 | L23: 2070 | M23: =L23-K23 -> 571 | N23: =IFERROR((L23-K23)/L23,"") -> 0.27584541 | O23: 1 | P23: peça única | Q23: em estoque | R23: não | S23: sim
A24: 20 | B24: iPhone | C24: iPhone 12 Pro | D24: 128GB | E24: Azul-pacífico | F24: Vitrine | G24: 80 | I24: 35325132294883 | J24: 09/08/2026 | K24: 1311 | L24: 1820 | M24: =L24-K24 -> 509 | N24: =IFERROR((L24-K24)/L24,"") -> 0.27967033 | O24: 1 | P24: peça única | Q24: em estoque | R24: não | S24: sim
A25: 21 | B25: iPhone | C25: iPhone 12 Pro Max | D25: 256GB | E25: Azul-pacífico | F25: Usado | G25: 90 | I25: 35543411514099 | J25: 10/08/2026 | K25: 1194 | L25: 1730 | M25: =L25-K25 -> 536 | N25: =IFERROR((L25-K25)/L25,"") -> 0.30982659 | O25: 1 | P25: peça única | Q25: em estoque | R25: não | S25: sim
A26: 22 | B26: iPhone | C26: iPhone 13 | D26: 128GB | E26: Verde | F26: Vitrine | G26: 84 | I26: 35533461684462 | J26: 01/08/2026 | K26: 1408 | L26: 1900 | M26: =L26-K26 -> 492 | N26: =IFERROR((L26-K26)/L26,"") -> 0.25894737 | O26: 1 | P26: peça única | Q26: em estoque | R26: não | S26: sim
A27: 23 | B27: iPhone | C27: iPhone 13 | D27: 512GB | E27: Estelar | F27: Vitrine | G27: 92 | I27: 35144523513599 | J27: 12/08/2026 | K27: 1614 | L27: 2100 | M27: =L27-K27 -> 486 | N27: =IFERROR((L27-K27)/L27,"") -> 0.23142857 | O27: 1 | P27: peça única | Q27: em estoque | R27: não | S27: sim
A28: 24 | B28: iPhone | C28: iPhone 13 Pro | D28: 512GB | E28: Prata | F28: Novo (lacrado) | G28: 100 | I28: 35548761430364 | J28: 11/08/2026 | K28: 2105 | L28: 2900 | M28: =L28-K28 -> 795 | N28: =IFERROR((L28-K28)/L28,"") -> 0.27413793 | O28: 1 | P28: peça única | Q28: em estoque | R28: não | S28: sim
A29: 25 | B29: iPhone | C29: iPhone 13 Pro | D29: 512GB | E29: Prata | F29: Usado | G29: 98 | H29: Tela riscada | I29: 35654127120855 | J29: 08/08/2026 | K29: 1318 | L29: 1790 | M29: =L29-K29 -> 472 | N29: =IFERROR((L29-K29)/L29,"") -> 0.26368715 | O29: 1 | P29: peça única | Q29: em estoque | R29: não | S29: sim
A30: 26 | B30: iPhone | C30: iPhone 13 Pro Max | D30: 256GB | E30: Verde-alpino | F30: Seminovo | G30: 98 | H30: Câmera com risco | I30: 35122492133226 | J30: 07/08/2026 | K30: 1859 | L30: 2520 | M30: =L30-K30 -> 661 | N30: =IFERROR((L30-K30)/L30,"") -> 0.26230159 | O30: 1 | P30: peça única | Q30: em estoque | R30: não | S30: sim
A31: 27 | B31: iPhone | C31: iPhone 13 Pro Max | D31: 512GB | E31: Grafite | F31: Seminovo | G31: 89 | H31: Face ID não funciona | I31: 35797199825160 | J31: 06/08/2026 | K31: 1697 | L31: 2130 | M31: =L31-K31 -> 433 | N31: =IFERROR((L31-K31)/L31,"") -> 0.20328638 | O31: 1 | P31: peça única | Q31: em estoque | R31: não | S31: sim
A32: 28 | B32: iPhone | C32: iPhone 13 Pro Max | D32: 256GB | E32: Verde-alpino | F32: Novo (lacrado) | G32: 100 | I32: 35972069464098 | J32: 12/08/2026 | K32: 2447 | L32: 3400 | M32: =L32-K32 -> 953 | N32: =IFERROR((L32-K32)/L32,"") -> 0.28029412 | O32: 1 | P32: peça única | Q32: em estoque | R32: não | S32: sim
A33: 29 | B33: iPhone | C33: iPhone 14 | D33: 512GB | E33: Roxo | F33: Seminovo | G33: 83 | I33: 35930104768981 | J33: 02/08/2026 | K33: 1572 | L33: 2010 | M33: =L33-K33 -> 438 | N33: =IFERROR((L33-K33)/L33,"") -> 0.21791045 | O33: 1 | P33: peça única | Q33: em estoque | R33: sim | S33: sim
A34: 30 | B34: iPhone | C34: iPhone 14 | D34: 128GB | E34: Azul | F34: Seminovo | G34: 77 | I34: 35757996749831 | J34: 06/08/2026 | K34: 1291 | L34: 1820 | M34: =L34-K34 -> 529 | N34: =IFERROR((L34-K34)/L34,"") -> 0.29065934 | O34: 1 | P34: peça única | Q34: em estoque | R34: sim | S34: sim
A35: 31 | B35: iPhone | C35: iPhone 14 | D35: 512GB | E35: Amarelo | F35: Usado | G35: 91 | I35: 35341892293722 | J35: 03/08/2026 | K35: 1381 | L35: 1820 | M35: =L35-K35 -> 439 | N35: =IFERROR((L35-K35)/L35,"") -> 0.24120879 | O35: 1 | P35: peça única | Q35: em estoque | R35: não | S35: sim
A36: 32 | B36: iPhone | C36: iPhone 14 Plus | D36: 256GB | E36: Meia-noite | F36: Novo (lacrado) | G36: 100 | I36: 35643650433457 | J36: 07/08/2026 | K36: 2224 | L36: 3200 | M36: =L36-K36 -> 976 | N36: =IFERROR((L36-K36)/L36,"") -> 0.305 | O36: 1 | P36: peça única | Q36: em estoque | R36: sim | S36: sim
A37: 33 | B37: iPhone | C37: iPhone 14 Pro | D37: 128GB | E37: Prata | F37: Seminovo | G37: 99 | I37: 35725980861389 | J37: 01/08/2026 | K37: 2259 | L37: 3040 | M37: =L37-K37 -> 781 | N37: =IFERROR((L37-K37)/L37,"") -> 0.25690789 | O37: 1 | P37: peça única | Q37: em estoque | R37: não | S37: sim
A38: 34 | B38: iPhone | C38: iPhone 14 Pro Max | D38: 256GB | E38: Preto-espacial | F38: Seminovo | G38: 79 | I38: 35345077715557 | J38: 01/08/2026 | K38: 1985 | L38: 2820 | M38: =L38-K38 -> 835 | N38: =IFERROR((L38-K38)/L38,"") -> 0.29609929 | O38: 1 | P38: peça única | Q38: em estoque | R38: não | S38: sim
A39: 35 | B39: iPhone | C39: iPhone 14 Pro Max | D39: 1TB | E39: Dourado | F39: Vitrine | G39: 94 | I39: 35556065791532 | J39: 04/08/2026 | K39: 3066 | L39: 3840 | M39: =L39-K39 -> 774 | N39: =IFERROR((L39-K39)/L39,"") -> 0.2015625 | O39: 1 | P39: peça única | Q39: em estoque | R39: não | S39: sim
A40: 36 | B40: iPhone | C40: iPhone 14 Pro Max | D40: 512GB | E40: Preto-espacial | F40: Vitrine | G40: 83 | I40: 35461755626794 | J40: 04/08/2026 | K40: 2618 | L40: 3480 | M40: =L40-K40 -> 862 | N40: =IFERROR((L40-K40)/L40,"") -> 0.24770115 | O40: 1 | P40: peça única | Q40: em estoque | R40: não | S40: sim
A41: 37 | B41: iPhone | C41: iPhone 15 | D41: 256GB | E41: Amarelo | F41: Seminovo | G41: 88 | I41: 35799237889283 | J41: 06/08/2026 | K41: 1963 | L41: 2680 | M41: =L41-K41 -> 717 | N41: =IFERROR((L41-K41)/L41,"") -> 0.26753731 | O41: 1 | P41: peça única | Q41: em estoque | R41: sim | S41: sim
...

Sheet Resumo
A1: Resumo por categoria
A2: Os números vêm da aba Catálogo — mexeu lá, muda aqui.
A4: Categoria | B4: Produtos | C4: Investido (custo) | D4: A receber (venda) | E4: Lucro previsto | F4: Margem
A5: iPhone | B5: =COUNTIF(Catálogo!$B$5:$B$93,$A5) -> 64 | C5: =SUMIF(Catálogo!$B$5:$B$93,$A5,Catálogo!$K$5:$K$93) -> 136789 | D5: =SUMIF(Catálogo!$B$5:$B$93,$A5,Catálogo!$L$5:$L$93) -> 183870 | E5: =D5-C5 -> 47081 | F5: =IFERROR(E5/D5,"") -> 0.25605591
A6: iPad | B6: =COUNTIF(Catálogo!$B$5:$B$93,$A6) -> 5 | C6: =SUMIF(Catálogo!$B$5:$B$93,$A6,Catálogo!$K$5:$K$93) -> 28085 | D6: =SUMIF(Catálogo!$B$5:$B$93,$A6,Catálogo!$L$5:$L$93) -> 35870 | E6: =D6-C6 -> 7785 | F6: =IFERROR(E6/D6,"") -> 0.21703373
A7: Apple Watch | B7: =COUNTIF(Catálogo!$B$5:$B$93,$A7) -> 3 | C7: =SUMIF(Catálogo!$B$5:$B$93,$A7,Catálogo!$K$5:$K$93) -> 12326 | D7: =SUMIF(Catálogo!$B$5:$B$93,$A7,Catálogo!$L$5:$L$93) -> 16340 | E7: =D7-C7 -> 4014 | F7: =IFERROR(E7/D7,"") -> 0.24565483
A8: MacBook | B8: =COUNTIF(Catálogo!$B$5:$B$93,$A8) -> 1 | C8: =SUMIF(Catálogo!$B$5:$B$93,$A8,Catálogo!$K$5:$K$93) -> 7885 | D8: =SUMIF(Catálogo!$B$5:$B$93,$A8,Catálogo!$L$5:$L$93) -> 11500 | E8: =D8-C8 -> 3615 | F8: =IFERROR(E8/D8,"") -> 0.31434783
A9: Motos elétricas | B9: =COUNTIF(Catálogo!$B$5:$B$93,$A9) -> 5 | C9: =SUMIF(Catálogo!$B$5:$B$93,$A9,Catálogo!$K$5:$K$93) -> 5258 | D9: =SUMIF(Catálogo!$B$5:$B$93,$A9,Catálogo!$L$5:$L$93) -> 8480 | E9: =D9-C9 -> 3222 | F9: =IFERROR(E9/D9,"") -> 0.37995283
A10: Acessórios | B10: =COUNTIF(Catálogo!$B$5:$B$93,$A10) -> 11 | C10: =SUMIF(Catálogo!$B$5:$B$93,$A10,Catálogo!$K$5:$K$93) -> 3667 | D10: =SUMIF(Catálogo!$B$5:$B$93,$A10,Catálogo!$L$5:$L$93) -> 5915 | E10: =D10-C10 -> 2248 | F10: =IFERROR(E10/D10,"") -> 0.38005072
A11: TOTAL | B11: =SUM(B5:B10) -> 89 | C11: =SUM(C5:C10) -> 194010 | D11: =SUM(D5:D10) -> 261975 | E11: =SUM(E5:E10) -> 67965 | F11: =IFERROR(E11/D11,"") -> 0.25943315

Sheet Ajuda
A1: Como ler esta planilha
A3: Coluna | B3: O que significa
A4: Custo | B4: O que você pagou no aparelho. É o número que você digita — pode corrigir aqui.
A5: Venda | B5: Preço pedido ao cliente. Também pode ser corrigido aqui.
A6: Lucro | B6: FÓRMULA: Venda menos Custo. Muda sozinho se você corrigir um dos dois.
A7: Margem | B7: FÓRMULA: quanto do preço de venda é lucro. 30% quer dizer que R$30 de cada R$100 sobram.
A8: Bateria % | B8: Saúde da bateria daquele aparelho. Vazio quer dizer acessório, ou aparelho lacrado.
A9: Avarias | B9: Defeitos declarados. Vazio quer dizer sem avaria.
A10: Controle | B10: «peça única» é aparelho com IMEI, contado um a um. «quantidade» é acessório, contado por unidade.
A11: Situação | B11: Se o item ainda está no estoque ou já foi vendido.
A12: Tem foto | B12: Se existe foto do produto no catálogo do cliente. «não» aparece com o contorno desenhado.
A13: Na vitrine | B13: Se o cliente enxerga esse item na loja. «não» fica só no seu controle interno.
A15: De onde vêm os dados
A16: Exportado do próprio sistema da loja, para a planilha nunca discordar do que está na tela. Para atualizar, exporte de novo e rode gerar_excel_catalogo.py.
A18: ATENÇÃO: os valores desta versão são dados de exemplo do protótipo, não o estoque real da loja.
